<mujoco model="box_1d">
    <compiler angle="degree" />
    <option timestep="0.001" gravity="0 0 -9.81" />

    <asset>
        <texture type="skybox" builtin="gradient" rgb1="0.3 0.5 0.7" rgb2="0 0 0" width="512" height="3072"/>
        <texture type="2d" name="groundplane" builtin="checker" mark="edge" rgb1="0.2 0.3 0.4" rgb2="0.1 0.2 0.3"
            markrgb="0.8 0.8 0.8" width="300" height="300"/>
        <material name="groundplane" texture="groundplane" texuniform="true" texrepeat="5 5" reflectance="0.2"/>
    </asset>

    <worldbody>
        <light pos="0 0 1.5" dir="0 0 -1" directional="true"/>
        <geom name="ground" type="plane" pos="0 0 0" size="0 0 0.1" material="groundplane" friction="1 0.005 0.0001"/>

        <body name="box" pos="0 0 0.5">
            <inertial pos="0 0 0" mass="1" diaginertia="0.1667 0.1667 0.1667"/>
            <geom name="box_geom" type="box" size="0.5 0.5 0.5"
                rgba="0.2 0.6 0.3 1" friction="0.8 0.1 0.1"/>
            <joint name="slider" type="slide" axis="1 0 0"/>
            <site name="box_site" pos="0 0 0" size="0.01" rgba="0 1 0 1"/>
        </body>
    </worldbody>
    <sensor>
        <jointpos name="box_x_pos" joint="slider"/>
        <jointvel name="box_x_vel" joint="slider"/>
        <!-- <accelerometer name="box_accel" site="box_site"/> -->
    </sensor>

    <actuator>
        <motor joint="slider" ctrlrange="-10 10" gear="1" />
    </actuator>
</mujoco>